ERROR 2023-06-13 08:48:07,786 log 15128 4440 Internal Server Error: /api/
Traceback (most recent call last):
  File "C:\Users\JSHARRATT\Documents\EES_GPT\backend\env\Lib\site-packages\django\core\handlers\exception.py", line 56, in inner
    response = get_response(request)
               ^^^^^^^^^^^^^^^^^^^^^
  File "C:\Users\JSHARRATT\Documents\EES_GPT\backend\env\Lib\site-packages\django\core\handlers\base.py", line 197, in _get_response
    response = wrapped_callback(request, *callback_args, **callback_kwargs)
               ^^^^^^^^^^^^^^^^^^^^^^^^^^^^^^^^^^^^^^^^^^^^^^^^^^^^^^^^^^^^
  File "C:\Users\JSHARRATT\Documents\EES_GPT\backend\env\Lib\site-packages\django\views\decorators\csrf.py", line 55, in wrapped_view
    return view_func(*args, **kwargs)
           ^^^^^^^^^^^^^^^^^^^^^^^^^^
  File "C:\Users\JSHARRATT\Documents\EES_GPT\backend\env\Lib\site-packages\django\views\generic\base.py", line 84, in view
    return self.dispatch(request, *args, **kwargs)
           ^^^^^^^^^^^^^^^^^^^^^^^^^^^^^^^^^^^^^^^
  File "C:\Users\JSHARRATT\Documents\EES_GPT\backend\env\Lib\site-packages\rest_framework\views.py", line 511, in dispatch
    self.response = self.finalize_response(request, response, *args, **kwargs)
                    ^^^^^^^^^^^^^^^^^^^^^^^^^^^^^^^^^^^^^^^^^^^^^^^^^^^^^^^^^^
  File "C:\Users\JSHARRATT\Documents\EES_GPT\backend\env\Lib\site-packages\rest_framework\views.py", line 423, in finalize_response
    assert isinstance(response, HttpResponseBase), (
AssertionError: Expected a `Response`, `HttpResponse` or `HttpStreamingResponse` to be returned from the view, but received a `<class 'coroutine'>`
ERROR 2023-06-13 09:01:01,811 log 16664 17076 Internal Server Error: /api/
Traceback (most recent call last):
  File "C:\Users\JSHARRATT\Documents\EES_GPT\backend\env\Lib\site-packages\django\core\handlers\exception.py", line 56, in inner
    response = get_response(request)
               ^^^^^^^^^^^^^^^^^^^^^
  File "C:\Users\JSHARRATT\Documents\EES_GPT\backend\env\Lib\site-packages\django\core\handlers\base.py", line 197, in _get_response
    response = wrapped_callback(request, *callback_args, **callback_kwargs)
               ^^^^^^^^^^^^^^^^^^^^^^^^^^^^^^^^^^^^^^^^^^^^^^^^^^^^^^^^^^^^
  File "C:\Users\JSHARRATT\Documents\EES_GPT\backend\env\Lib\site-packages\asgiref\sync.py", line 277, in __call__
    return call_result.result()
           ^^^^^^^^^^^^^^^^^^^^
  File "C:\Program Files\Python311\Lib\concurrent\futures\_base.py", line 449, in result
    return self.__get_result()
           ^^^^^^^^^^^^^^^^^^^
  File "C:\Program Files\Python311\Lib\concurrent\futures\_base.py", line 401, in __get_result
    raise self._exception
  File "C:\Users\JSHARRATT\Documents\EES_GPT\backend\env\Lib\site-packages\asgiref\sync.py", line 353, in main_wrap
    result = await self.awaitable(*args, **kwargs)
             ^^^^^^^^^^^^^^^^^^^^^^^^^^^^^^^^^^^^^
  File "C:\Users\JSHARRATT\Documents\EES_GPT\backend\env\Lib\site-packages\asgiref\sync.py", line 479, in __call__
    ret: _R = await loop.run_in_executor(
              ^^^^^^^^^^^^^^^^^^^^^^^^^^^
  File "C:\Users\JSHARRATT\Documents\EES_GPT\backend\env\Lib\site-packages\asgiref\current_thread_executor.py", line 40, in run
    result = self.fn(*self.args, **self.kwargs)
             ^^^^^^^^^^^^^^^^^^^^^^^^^^^^^^^^^^
  File "C:\Users\JSHARRATT\Documents\EES_GPT\backend\env\Lib\site-packages\asgiref\sync.py", line 538, in thread_handler
    return func(*args, **kwargs)
           ^^^^^^^^^^^^^^^^^^^^^
  File "C:\Users\JSHARRATT\Documents\EES_GPT\backend\env\Lib\site-packages\django\views\decorators\csrf.py", line 55, in wrapped_view
    return view_func(*args, **kwargs)
           ^^^^^^^^^^^^^^^^^^^^^^^^^^
  File "C:\Users\JSHARRATT\Documents\EES_GPT\backend\env\Lib\site-packages\django\views\generic\base.py", line 84, in view
    return self.dispatch(request, *args, **kwargs)
           ^^^^^^^^^^^^^^^^^^^^^^^^^^^^^^^^^^^^^^^
  File "C:\Users\JSHARRATT\Documents\EES_GPT\backend\env\Lib\site-packages\rest_framework\views.py", line 511, in dispatch
    self.response = self.finalize_response(request, response, *args, **kwargs)
                    ^^^^^^^^^^^^^^^^^^^^^^^^^^^^^^^^^^^^^^^^^^^^^^^^^^^^^^^^^^
  File "C:\Users\JSHARRATT\Documents\EES_GPT\backend\env\Lib\site-packages\rest_framework\views.py", line 423, in finalize_response
    assert isinstance(response, HttpResponseBase), (
AssertionError: Expected a `Response`, `HttpResponse` or `HttpStreamingResponse` to be returned from the view, but received a `<class 'coroutine'>`
ERROR 2023-06-13 09:07:55,272 log 15592 1800 Internal Server Error: /api/
Traceback (most recent call last):
  File "C:\Users\JSHARRATT\Documents\EES_GPT\backend\env\Lib\site-packages\django\core\handlers\exception.py", line 55, in inner
    response = get_response(request)
               ^^^^^^^^^^^^^^^^^^^^^
  File "C:\Users\JSHARRATT\Documents\EES_GPT\backend\env\Lib\site-packages\django\core\handlers\base.py", line 197, in _get_response
    response = wrapped_callback(request, *callback_args, **callback_kwargs)
               ^^^^^^^^^^^^^^^^^^^^^^^^^^^^^^^^^^^^^^^^^^^^^^^^^^^^^^^^^^^^
  File "C:\Users\JSHARRATT\Documents\EES_GPT\backend\env\Lib\site-packages\asgiref\sync.py", line 277, in __call__
    return call_result.result()
           ^^^^^^^^^^^^^^^^^^^^
  File "C:\Program Files\Python311\Lib\concurrent\futures\_base.py", line 449, in result
    return self.__get_result()
           ^^^^^^^^^^^^^^^^^^^
  File "C:\Program Files\Python311\Lib\concurrent\futures\_base.py", line 401, in __get_result
    raise self._exception
  File "C:\Users\JSHARRATT\Documents\EES_GPT\backend\env\Lib\site-packages\asgiref\sync.py", line 353, in main_wrap
    result = await self.awaitable(*args, **kwargs)
             ^^^^^^^^^^^^^^^^^^^^^^^^^^^^^^^^^^^^^
  File "C:\Users\JSHARRATT\Documents\EES_GPT\backend\env\Lib\site-packages\asgiref\sync.py", line 479, in __call__
    ret: _R = await loop.run_in_executor(
              ^^^^^^^^^^^^^^^^^^^^^^^^^^^
  File "C:\Users\JSHARRATT\Documents\EES_GPT\backend\env\Lib\site-packages\asgiref\current_thread_executor.py", line 40, in run
    result = self.fn(*self.args, **self.kwargs)
             ^^^^^^^^^^^^^^^^^^^^^^^^^^^^^^^^^^
  File "C:\Users\JSHARRATT\Documents\EES_GPT\backend\env\Lib\site-packages\asgiref\sync.py", line 538, in thread_handler
    return func(*args, **kwargs)
           ^^^^^^^^^^^^^^^^^^^^^
  File "C:\Users\JSHARRATT\Documents\EES_GPT\backend\env\Lib\site-packages\django\views\decorators\csrf.py", line 56, in wrapper_view
    return view_func(*args, **kwargs)
           ^^^^^^^^^^^^^^^^^^^^^^^^^^
  File "C:\Users\JSHARRATT\Documents\EES_GPT\backend\env\Lib\site-packages\django\views\generic\base.py", line 104, in view
    return self.dispatch(request, *args, **kwargs)
           ^^^^^^^^^^^^^^^^^^^^^^^^^^^^^^^^^^^^^^^
  File "C:\Users\JSHARRATT\Documents\EES_GPT\backend\env\Lib\site-packages\rest_framework\views.py", line 511, in dispatch
    self.response = self.finalize_response(request, response, *args, **kwargs)
                    ^^^^^^^^^^^^^^^^^^^^^^^^^^^^^^^^^^^^^^^^^^^^^^^^^^^^^^^^^^
  File "C:\Users\JSHARRATT\Documents\EES_GPT\backend\env\Lib\site-packages\rest_framework\views.py", line 423, in finalize_response
    assert isinstance(response, HttpResponseBase), (
AssertionError: Expected a `Response`, `HttpResponse` or `HttpStreamingResponse` to be returned from the view, but received a `<class 'coroutine'>`
ERROR 2023-06-13 09:14:53,916 log 15968 9300 Internal Server Error: /api/
Traceback (most recent call last):
  File "C:\Users\JSHARRATT\Documents\EES_GPT\backend\env\Lib\site-packages\django\core\handlers\exception.py", line 55, in inner
    response = get_response(request)
               ^^^^^^^^^^^^^^^^^^^^^
  File "C:\Users\JSHARRATT\Documents\EES_GPT\backend\env\Lib\site-packages\django\core\handlers\base.py", line 197, in _get_response
    response = wrapped_callback(request, *callback_args, **callback_kwargs)
               ^^^^^^^^^^^^^^^^^^^^^^^^^^^^^^^^^^^^^^^^^^^^^^^^^^^^^^^^^^^^
  File "C:\Users\JSHARRATT\Documents\EES_GPT\backend\env\Lib\site-packages\asgiref\sync.py", line 277, in __call__
    return call_result.result()
           ^^^^^^^^^^^^^^^^^^^^
  File "C:\Program Files\Python311\Lib\concurrent\futures\_base.py", line 449, in result
    return self.__get_result()
           ^^^^^^^^^^^^^^^^^^^
  File "C:\Program Files\Python311\Lib\concurrent\futures\_base.py", line 401, in __get_result
    raise self._exception
  File "C:\Users\JSHARRATT\Documents\EES_GPT\backend\env\Lib\site-packages\asgiref\sync.py", line 353, in main_wrap
    result = await self.awaitable(*args, **kwargs)
             ^^^^^^^^^^^^^^^^^^^^^^^^^^^^^^^^^^^^^
  File "C:\Users\JSHARRATT\Documents\EES_GPT\backend\env\Lib\site-packages\adrf\views.py", line 63, in async_dispatch
    response = self.handle_exception(exc)
               ^^^^^^^^^^^^^^^^^^^^^^^^^^
  File "C:\Users\JSHARRATT\Documents\EES_GPT\backend\env\Lib\site-packages\rest_framework\views.py", line 469, in handle_exception
    self.raise_uncaught_exception(exc)
  File "C:\Users\JSHARRATT\Documents\EES_GPT\backend\env\Lib\site-packages\rest_framework\views.py", line 480, in raise_uncaught_exception
    raise exc
  File "C:\Users\JSHARRATT\Documents\EES_GPT\backend\env\Lib\site-packages\adrf\views.py", line 60, in async_dispatch
    response = await handler(request, *args, **kwargs)
               ^^^^^^^^^^^^^^^^^^^^^^^^^^^^^^^^^^^^^^^
  File "C:\Users\JSHARRATT\Documents\EES_GPT\backend\env\Lib\site-packages\adrf\decorators.py", line 44, in handler
    return await func(*args, **kwargs)
           ^^^^^^^^^^^^^^^^^^^^^^^^^^^
  File "C:\Users\JSHARRATT\Documents\EES_GPT\backend\django_proj\api\views.py", line 39, in handler
    vector_store = await Pinecone.from_existing_index(index_name='edtech-gpt',
                   ^^^^^^^^^^^^^^^^^^^^^^^^^^^^^^^^^^^^^^^^^^^^^^^^^^^^^^^^^^^
TypeError: object Pinecone can't be used in 'await' expression
ERROR 2023-06-13 09:17:13,485 views 16116 16584 Failed with error object dict can't be used in 'await' expression
ERROR 2023-06-13 09:20:41,684 views 16968 3380 Failed with error 'coroutine' object is not callable
ERROR 2023-06-13 09:22:30,141 views 5240 16632 Failed with error 'coroutine' object is not callable
ERROR 2023-06-13 10:04:46,498 views 6304 13760 Failed with error object dict can't be used in 'await' expression
ERROR 2023-06-13 10:07:41,285 views 7520 9000 Failed with error 'ConversationalRetrievalChain' object has no attribute 'call'
ERROR 2023-06-13 11:26:55,923 views 19372 8280 Failed with error string indices must be integers, not 'str'
