ERROR 2023-06-13 08:48:07,786 log 15128 4440 Internal Server Error: /api/
Traceback (most recent call last):
  File "C:\Users\JSHARRATT\Documents\EES_GPT\backend\env\Lib\site-packages\django\core\handlers\exception.py", line 56, in inner
    response = get_response(request)
               ^^^^^^^^^^^^^^^^^^^^^
  File "C:\Users\JSHARRATT\Documents\EES_GPT\backend\env\Lib\site-packages\django\core\handlers\base.py", line 197, in _get_response
    response = wrapped_callback(request, *callback_args, **callback_kwargs)
               ^^^^^^^^^^^^^^^^^^^^^^^^^^^^^^^^^^^^^^^^^^^^^^^^^^^^^^^^^^^^
  File "C:\Users\JSHARRATT\Documents\EES_GPT\backend\env\Lib\site-packages\django\views\decorators\csrf.py", line 55, in wrapped_view
    return view_func(*args, **kwargs)
           ^^^^^^^^^^^^^^^^^^^^^^^^^^
  File "C:\Users\JSHARRATT\Documents\EES_GPT\backend\env\Lib\site-packages\django\views\generic\base.py", line 84, in view
    return self.dispatch(request, *args, **kwargs)
           ^^^^^^^^^^^^^^^^^^^^^^^^^^^^^^^^^^^^^^^
  File "C:\Users\JSHARRATT\Documents\EES_GPT\backend\env\Lib\site-packages\rest_framework\views.py", line 511, in dispatch
    self.response = self.finalize_response(request, response, *args, **kwargs)
                    ^^^^^^^^^^^^^^^^^^^^^^^^^^^^^^^^^^^^^^^^^^^^^^^^^^^^^^^^^^
  File "C:\Users\JSHARRATT\Documents\EES_GPT\backend\env\Lib\site-packages\rest_framework\views.py", line 423, in finalize_response
    assert isinstance(response, HttpResponseBase), (
AssertionError: Expected a `Response`, `HttpResponse` or `HttpStreamingResponse` to be returned from the view, but received a `<class 'coroutine'>`
ERROR 2023-06-13 09:01:01,811 log 16664 17076 Internal Server Error: /api/
Traceback (most recent call last):
  File "C:\Users\JSHARRATT\Documents\EES_GPT\backend\env\Lib\site-packages\django\core\handlers\exception.py", line 56, in inner
    response = get_response(request)
               ^^^^^^^^^^^^^^^^^^^^^
  File "C:\Users\JSHARRATT\Documents\EES_GPT\backend\env\Lib\site-packages\django\core\handlers\base.py", line 197, in _get_response
    response = wrapped_callback(request, *callback_args, **callback_kwargs)
               ^^^^^^^^^^^^^^^^^^^^^^^^^^^^^^^^^^^^^^^^^^^^^^^^^^^^^^^^^^^^
  File "C:\Users\JSHARRATT\Documents\EES_GPT\backend\env\Lib\site-packages\asgiref\sync.py", line 277, in __call__
    return call_result.result()
           ^^^^^^^^^^^^^^^^^^^^
  File "C:\Program Files\Python311\Lib\concurrent\futures\_base.py", line 449, in result
    return self.__get_result()
           ^^^^^^^^^^^^^^^^^^^
  File "C:\Program Files\Python311\Lib\concurrent\futures\_base.py", line 401, in __get_result
    raise self._exception
  File "C:\Users\JSHARRATT\Documents\EES_GPT\backend\env\Lib\site-packages\asgiref\sync.py", line 353, in main_wrap
    result = await self.awaitable(*args, **kwargs)
             ^^^^^^^^^^^^^^^^^^^^^^^^^^^^^^^^^^^^^
  File "C:\Users\JSHARRATT\Documents\EES_GPT\backend\env\Lib\site-packages\asgiref\sync.py", line 479, in __call__
    ret: _R = await loop.run_in_executor(
              ^^^^^^^^^^^^^^^^^^^^^^^^^^^
  File "C:\Users\JSHARRATT\Documents\EES_GPT\backend\env\Lib\site-packages\asgiref\current_thread_executor.py", line 40, in run
    result = self.fn(*self.args, **self.kwargs)
             ^^^^^^^^^^^^^^^^^^^^^^^^^^^^^^^^^^
  File "C:\Users\JSHARRATT\Documents\EES_GPT\backend\env\Lib\site-packages\asgiref\sync.py", line 538, in thread_handler
    return func(*args, **kwargs)
           ^^^^^^^^^^^^^^^^^^^^^
  File "C:\Users\JSHARRATT\Documents\EES_GPT\backend\env\Lib\site-packages\django\views\decorators\csrf.py", line 55, in wrapped_view
    return view_func(*args, **kwargs)
           ^^^^^^^^^^^^^^^^^^^^^^^^^^
  File "C:\Users\JSHARRATT\Documents\EES_GPT\backend\env\Lib\site-packages\django\views\generic\base.py", line 84, in view
    return self.dispatch(request, *args, **kwargs)
           ^^^^^^^^^^^^^^^^^^^^^^^^^^^^^^^^^^^^^^^
  File "C:\Users\JSHARRATT\Documents\EES_GPT\backend\env\Lib\site-packages\rest_framework\views.py", line 511, in dispatch
    self.response = self.finalize_response(request, response, *args, **kwargs)
                    ^^^^^^^^^^^^^^^^^^^^^^^^^^^^^^^^^^^^^^^^^^^^^^^^^^^^^^^^^^
  File "C:\Users\JSHARRATT\Documents\EES_GPT\backend\env\Lib\site-packages\rest_framework\views.py", line 423, in finalize_response
    assert isinstance(response, HttpResponseBase), (
AssertionError: Expected a `Response`, `HttpResponse` or `HttpStreamingResponse` to be returned from the view, but received a `<class 'coroutine'>`
ERROR 2023-06-13 09:07:55,272 log 15592 1800 Internal Server Error: /api/
Traceback (most recent call last):
  File "C:\Users\JSHARRATT\Documents\EES_GPT\backend\env\Lib\site-packages\django\core\handlers\exception.py", line 55, in inner
    response = get_response(request)
               ^^^^^^^^^^^^^^^^^^^^^
  File "C:\Users\JSHARRATT\Documents\EES_GPT\backend\env\Lib\site-packages\django\core\handlers\base.py", line 197, in _get_response
    response = wrapped_callback(request, *callback_args, **callback_kwargs)
               ^^^^^^^^^^^^^^^^^^^^^^^^^^^^^^^^^^^^^^^^^^^^^^^^^^^^^^^^^^^^
  File "C:\Users\JSHARRATT\Documents\EES_GPT\backend\env\Lib\site-packages\asgiref\sync.py", line 277, in __call__
    return call_result.result()
           ^^^^^^^^^^^^^^^^^^^^
  File "C:\Program Files\Python311\Lib\concurrent\futures\_base.py", line 449, in result
    return self.__get_result()
           ^^^^^^^^^^^^^^^^^^^
  File "C:\Program Files\Python311\Lib\concurrent\futures\_base.py", line 401, in __get_result
    raise self._exception
  File "C:\Users\JSHARRATT\Documents\EES_GPT\backend\env\Lib\site-packages\asgiref\sync.py", line 353, in main_wrap
    result = await self.awaitable(*args, **kwargs)
             ^^^^^^^^^^^^^^^^^^^^^^^^^^^^^^^^^^^^^
  File "C:\Users\JSHARRATT\Documents\EES_GPT\backend\env\Lib\site-packages\asgiref\sync.py", line 479, in __call__
    ret: _R = await loop.run_in_executor(
              ^^^^^^^^^^^^^^^^^^^^^^^^^^^
  File "C:\Users\JSHARRATT\Documents\EES_GPT\backend\env\Lib\site-packages\asgiref\current_thread_executor.py", line 40, in run
    result = self.fn(*self.args, **self.kwargs)
             ^^^^^^^^^^^^^^^^^^^^^^^^^^^^^^^^^^
  File "C:\Users\JSHARRATT\Documents\EES_GPT\backend\env\Lib\site-packages\asgiref\sync.py", line 538, in thread_handler
    return func(*args, **kwargs)
           ^^^^^^^^^^^^^^^^^^^^^
  File "C:\Users\JSHARRATT\Documents\EES_GPT\backend\env\Lib\site-packages\django\views\decorators\csrf.py", line 56, in wrapper_view
    return view_func(*args, **kwargs)
           ^^^^^^^^^^^^^^^^^^^^^^^^^^
  File "C:\Users\JSHARRATT\Documents\EES_GPT\backend\env\Lib\site-packages\django\views\generic\base.py", line 104, in view
    return self.dispatch(request, *args, **kwargs)
           ^^^^^^^^^^^^^^^^^^^^^^^^^^^^^^^^^^^^^^^
  File "C:\Users\JSHARRATT\Documents\EES_GPT\backend\env\Lib\site-packages\rest_framework\views.py", line 511, in dispatch
    self.response = self.finalize_response(request, response, *args, **kwargs)
                    ^^^^^^^^^^^^^^^^^^^^^^^^^^^^^^^^^^^^^^^^^^^^^^^^^^^^^^^^^^
  File "C:\Users\JSHARRATT\Documents\EES_GPT\backend\env\Lib\site-packages\rest_framework\views.py", line 423, in finalize_response
    assert isinstance(response, HttpResponseBase), (
AssertionError: Expected a `Response`, `HttpResponse` or `HttpStreamingResponse` to be returned from the view, but received a `<class 'coroutine'>`
ERROR 2023-06-13 09:14:53,916 log 15968 9300 Internal Server Error: /api/
Traceback (most recent call last):
  File "C:\Users\JSHARRATT\Documents\EES_GPT\backend\env\Lib\site-packages\django\core\handlers\exception.py", line 55, in inner
    response = get_response(request)
               ^^^^^^^^^^^^^^^^^^^^^
  File "C:\Users\JSHARRATT\Documents\EES_GPT\backend\env\Lib\site-packages\django\core\handlers\base.py", line 197, in _get_response
    response = wrapped_callback(request, *callback_args, **callback_kwargs)
               ^^^^^^^^^^^^^^^^^^^^^^^^^^^^^^^^^^^^^^^^^^^^^^^^^^^^^^^^^^^^
  File "C:\Users\JSHARRATT\Documents\EES_GPT\backend\env\Lib\site-packages\asgiref\sync.py", line 277, in __call__
    return call_result.result()
           ^^^^^^^^^^^^^^^^^^^^
  File "C:\Program Files\Python311\Lib\concurrent\futures\_base.py", line 449, in result
    return self.__get_result()
           ^^^^^^^^^^^^^^^^^^^
  File "C:\Program Files\Python311\Lib\concurrent\futures\_base.py", line 401, in __get_result
    raise self._exception
  File "C:\Users\JSHARRATT\Documents\EES_GPT\backend\env\Lib\site-packages\asgiref\sync.py", line 353, in main_wrap
    result = await self.awaitable(*args, **kwargs)
             ^^^^^^^^^^^^^^^^^^^^^^^^^^^^^^^^^^^^^
  File "C:\Users\JSHARRATT\Documents\EES_GPT\backend\env\Lib\site-packages\adrf\views.py", line 63, in async_dispatch
    response = self.handle_exception(exc)
               ^^^^^^^^^^^^^^^^^^^^^^^^^^
  File "C:\Users\JSHARRATT\Documents\EES_GPT\backend\env\Lib\site-packages\rest_framework\views.py", line 469, in handle_exception
    self.raise_uncaught_exception(exc)
  File "C:\Users\JSHARRATT\Documents\EES_GPT\backend\env\Lib\site-packages\rest_framework\views.py", line 480, in raise_uncaught_exception
    raise exc
  File "C:\Users\JSHARRATT\Documents\EES_GPT\backend\env\Lib\site-packages\adrf\views.py", line 60, in async_dispatch
    response = await handler(request, *args, **kwargs)
               ^^^^^^^^^^^^^^^^^^^^^^^^^^^^^^^^^^^^^^^
  File "C:\Users\JSHARRATT\Documents\EES_GPT\backend\env\Lib\site-packages\adrf\decorators.py", line 44, in handler
    return await func(*args, **kwargs)
           ^^^^^^^^^^^^^^^^^^^^^^^^^^^
  File "C:\Users\JSHARRATT\Documents\EES_GPT\backend\django_proj\api\views.py", line 39, in handler
    vector_store = await Pinecone.from_existing_index(index_name='edtech-gpt',
                   ^^^^^^^^^^^^^^^^^^^^^^^^^^^^^^^^^^^^^^^^^^^^^^^^^^^^^^^^^^^
TypeError: object Pinecone can't be used in 'await' expression
ERROR 2023-06-13 09:17:13,485 views 16116 16584 Failed with error object dict can't be used in 'await' expression
ERROR 2023-06-13 09:20:41,684 views 16968 3380 Failed with error 'coroutine' object is not callable
ERROR 2023-06-13 09:22:30,141 views 5240 16632 Failed with error 'coroutine' object is not callable
ERROR 2023-06-13 10:04:46,498 views 6304 13760 Failed with error object dict can't be used in 'await' expression
ERROR 2023-06-13 10:07:41,285 views 7520 9000 Failed with error 'ConversationalRetrievalChain' object has no attribute 'call'
ERROR 2023-06-13 11:26:55,923 views 19372 8280 Failed with error string indices must be integers, not 'str'
ERROR 2023-06-13 13:32:21,589 views 14624 3420 Failed with error Incorrect API key provided: sk-fmauc***************************************y0PO. You can find your API key at https://platform.openai.com/account/api-keys.
ERROR 2023-06-13 13:33:22,058 log 14624 17164 Internal Server Error: /api/
Traceback (most recent call last):
  File "C:\Users\JSHARRATT\Documents\EES_GPT\backend\env\Lib\site-packages\django\core\handlers\exception.py", line 55, in inner
    response = get_response(request)
               ^^^^^^^^^^^^^^^^^^^^^
  File "C:\Users\JSHARRATT\Documents\EES_GPT\backend\env\Lib\site-packages\django\core\handlers\base.py", line 197, in _get_response
    response = wrapped_callback(request, *callback_args, **callback_kwargs)
               ^^^^^^^^^^^^^^^^^^^^^^^^^^^^^^^^^^^^^^^^^^^^^^^^^^^^^^^^^^^^
  File "C:\Users\JSHARRATT\Documents\EES_GPT\backend\env\Lib\site-packages\asgiref\sync.py", line 277, in __call__
    return call_result.result()
           ^^^^^^^^^^^^^^^^^^^^
  File "C:\Program Files\Python311\Lib\concurrent\futures\_base.py", line 449, in result
    return self.__get_result()
           ^^^^^^^^^^^^^^^^^^^
  File "C:\Program Files\Python311\Lib\concurrent\futures\_base.py", line 401, in __get_result
    raise self._exception
  File "C:\Users\JSHARRATT\Documents\EES_GPT\backend\env\Lib\site-packages\asgiref\sync.py", line 353, in main_wrap
    result = await self.awaitable(*args, **kwargs)
             ^^^^^^^^^^^^^^^^^^^^^^^^^^^^^^^^^^^^^
  File "C:\Users\JSHARRATT\Documents\EES_GPT\backend\env\Lib\site-packages\adrf\views.py", line 63, in async_dispatch
    response = self.handle_exception(exc)
               ^^^^^^^^^^^^^^^^^^^^^^^^^^
  File "C:\Users\JSHARRATT\Documents\EES_GPT\backend\env\Lib\site-packages\rest_framework\views.py", line 469, in handle_exception
    self.raise_uncaught_exception(exc)
  File "C:\Users\JSHARRATT\Documents\EES_GPT\backend\env\Lib\site-packages\rest_framework\views.py", line 480, in raise_uncaught_exception
    raise exc
  File "C:\Users\JSHARRATT\Documents\EES_GPT\backend\env\Lib\site-packages\adrf\views.py", line 60, in async_dispatch
    response = await handler(request, *args, **kwargs)
               ^^^^^^^^^^^^^^^^^^^^^^^^^^^^^^^^^^^^^^^
  File "C:\Users\JSHARRATT\Documents\EES_GPT\backend\env\Lib\site-packages\adrf\decorators.py", line 44, in handler
    return await func(*args, **kwargs)
           ^^^^^^^^^^^^^^^^^^^^^^^^^^^
  File "C:\Users\JSHARRATT\Documents\EES_GPT\backend\django_proj\api\views.py", line 37, in handler
    similar_docs = vector_store.similarity_search(query = stripped_question, int = 4)
                   ^^^^^^^^^^^^^^^^^^^^^^^^^^^^^^^^^^^^^^^^^^^^^^^^^^^^^^^^^^^^^^^^^^
  File "C:\Users\JSHARRATT\Documents\EES_GPT\backend\env\Lib\site-packages\langchain\vectorstores\pinecone.py", line 148, in similarity_search
    query_obj = self._embedding_function(query)
                ^^^^^^^^^^^^^^^^^^^^^^^^^^^^^^^
  File "C:\Users\JSHARRATT\Documents\EES_GPT\backend\env\Lib\site-packages\langchain\embeddings\openai.py", line 280, in embed_query
    embedding = self._embedding_func(text, engine=self.query_model_name)
                ^^^^^^^^^^^^^^^^^^^^^^^^^^^^^^^^^^^^^^^^^^^^^^^^^^^^^^^^
  File "C:\Users\JSHARRATT\Documents\EES_GPT\backend\env\Lib\site-packages\langchain\embeddings\openai.py", line 236, in _embedding_func
    return self._get_len_safe_embeddings([text], engine=engine)[0]
           ^^^^^^^^^^^^^^^^^^^^^^^^^^^^^^^^^^^^^^^^^^^^^^^^^^^^
  File "C:\Users\JSHARRATT\Documents\EES_GPT\backend\env\Lib\site-packages\langchain\embeddings\openai.py", line 206, in _get_len_safe_embeddings
    response = embed_with_retry(
               ^^^^^^^^^^^^^^^^^
  File "C:\Users\JSHARRATT\Documents\EES_GPT\backend\env\Lib\site-packages\langchain\embeddings\openai.py", line 53, in embed_with_retry
    return _completion_with_retry(**kwargs)
           ^^^^^^^^^^^^^^^^^^^^^^^^^^^^^^^^
  File "C:\Users\JSHARRATT\Documents\EES_GPT\backend\env\Lib\site-packages\tenacity\__init__.py", line 289, in wrapped_f
    return self(f, *args, **kw)
           ^^^^^^^^^^^^^^^^^^^^
  File "C:\Users\JSHARRATT\Documents\EES_GPT\backend\env\Lib\site-packages\tenacity\__init__.py", line 379, in __call__
    do = self.iter(retry_state=retry_state)
         ^^^^^^^^^^^^^^^^^^^^^^^^^^^^^^^^^^
  File "C:\Users\JSHARRATT\Documents\EES_GPT\backend\env\Lib\site-packages\tenacity\__init__.py", line 314, in iter
    return fut.result()
           ^^^^^^^^^^^^
  File "C:\Program Files\Python311\Lib\concurrent\futures\_base.py", line 449, in result
    return self.__get_result()
           ^^^^^^^^^^^^^^^^^^^
  File "C:\Program Files\Python311\Lib\concurrent\futures\_base.py", line 401, in __get_result
    raise self._exception
  File "C:\Users\JSHARRATT\Documents\EES_GPT\backend\env\Lib\site-packages\tenacity\__init__.py", line 382, in __call__
    result = fn(*args, **kwargs)
             ^^^^^^^^^^^^^^^^^^^
  File "C:\Users\JSHARRATT\Documents\EES_GPT\backend\env\Lib\site-packages\langchain\embeddings\openai.py", line 51, in _completion_with_retry
    return embeddings.client.create(**kwargs)
           ^^^^^^^^^^^^^^^^^^^^^^^^^^^^^^^^^^
  File "C:\Users\JSHARRATT\Documents\EES_GPT\backend\env\Lib\site-packages\openai\api_resources\embedding.py", line 33, in create
    response = super().create(*args, **kwargs)
               ^^^^^^^^^^^^^^^^^^^^^^^^^^^^^^^
  File "C:\Users\JSHARRATT\Documents\EES_GPT\backend\env\Lib\site-packages\openai\api_resources\abstract\engine_api_resource.py", line 153, in create
    response, _, api_key = requestor.request(
                           ^^^^^^^^^^^^^^^^^^
  File "C:\Users\JSHARRATT\Documents\EES_GPT\backend\env\Lib\site-packages\openai\api_requestor.py", line 298, in request
    resp, got_stream = self._interpret_response(result, stream)
                       ^^^^^^^^^^^^^^^^^^^^^^^^^^^^^^^^^^^^^^^^
  File "C:\Users\JSHARRATT\Documents\EES_GPT\backend\env\Lib\site-packages\openai\api_requestor.py", line 700, in _interpret_response
    self._interpret_response_line(
  File "C:\Users\JSHARRATT\Documents\EES_GPT\backend\env\Lib\site-packages\openai\api_requestor.py", line 763, in _interpret_response_line
    raise self.handle_error_response(
openai.error.AuthenticationError: <empty message>
ERROR 2023-06-13 13:34:26,632 log 14624 3440 Internal Server Error: /api/
Traceback (most recent call last):
  File "C:\Users\JSHARRATT\Documents\EES_GPT\backend\env\Lib\site-packages\django\core\handlers\exception.py", line 55, in inner
    response = get_response(request)
               ^^^^^^^^^^^^^^^^^^^^^
  File "C:\Users\JSHARRATT\Documents\EES_GPT\backend\env\Lib\site-packages\django\core\handlers\base.py", line 197, in _get_response
    response = wrapped_callback(request, *callback_args, **callback_kwargs)
               ^^^^^^^^^^^^^^^^^^^^^^^^^^^^^^^^^^^^^^^^^^^^^^^^^^^^^^^^^^^^
  File "C:\Users\JSHARRATT\Documents\EES_GPT\backend\env\Lib\site-packages\asgiref\sync.py", line 277, in __call__
    return call_result.result()
           ^^^^^^^^^^^^^^^^^^^^
  File "C:\Program Files\Python311\Lib\concurrent\futures\_base.py", line 449, in result
    return self.__get_result()
           ^^^^^^^^^^^^^^^^^^^
  File "C:\Program Files\Python311\Lib\concurrent\futures\_base.py", line 401, in __get_result
    raise self._exception
  File "C:\Users\JSHARRATT\Documents\EES_GPT\backend\env\Lib\site-packages\asgiref\sync.py", line 353, in main_wrap
    result = await self.awaitable(*args, **kwargs)
             ^^^^^^^^^^^^^^^^^^^^^^^^^^^^^^^^^^^^^
  File "C:\Users\JSHARRATT\Documents\EES_GPT\backend\env\Lib\site-packages\adrf\views.py", line 63, in async_dispatch
    response = self.handle_exception(exc)
               ^^^^^^^^^^^^^^^^^^^^^^^^^^
  File "C:\Users\JSHARRATT\Documents\EES_GPT\backend\env\Lib\site-packages\rest_framework\views.py", line 469, in handle_exception
    self.raise_uncaught_exception(exc)
  File "C:\Users\JSHARRATT\Documents\EES_GPT\backend\env\Lib\site-packages\rest_framework\views.py", line 480, in raise_uncaught_exception
    raise exc
  File "C:\Users\JSHARRATT\Documents\EES_GPT\backend\env\Lib\site-packages\adrf\views.py", line 60, in async_dispatch
    response = await handler(request, *args, **kwargs)
               ^^^^^^^^^^^^^^^^^^^^^^^^^^^^^^^^^^^^^^^
  File "C:\Users\JSHARRATT\Documents\EES_GPT\backend\env\Lib\site-packages\adrf\decorators.py", line 44, in handler
    return await func(*args, **kwargs)
           ^^^^^^^^^^^^^^^^^^^^^^^^^^^
  File "C:\Users\JSHARRATT\Documents\EES_GPT\backend\django_proj\api\views.py", line 37, in handler
    similar_docs = vector_store.similarity_search(query = stripped_question, int = 4)
                   ^^^^^^^^^^^^^^^^^^^^^^^^^^^^^^^^^^^^^^^^^^^^^^^^^^^^^^^^^^^^^^^^^^
  File "C:\Users\JSHARRATT\Documents\EES_GPT\backend\env\Lib\site-packages\langchain\vectorstores\pinecone.py", line 148, in similarity_search
    query_obj = self._embedding_function(query)
                ^^^^^^^^^^^^^^^^^^^^^^^^^^^^^^^
  File "C:\Users\JSHARRATT\Documents\EES_GPT\backend\env\Lib\site-packages\langchain\embeddings\openai.py", line 280, in embed_query
    embedding = self._embedding_func(text, engine=self.query_model_name)
                ^^^^^^^^^^^^^^^^^^^^^^^^^^^^^^^^^^^^^^^^^^^^^^^^^^^^^^^^
  File "C:\Users\JSHARRATT\Documents\EES_GPT\backend\env\Lib\site-packages\langchain\embeddings\openai.py", line 236, in _embedding_func
    return self._get_len_safe_embeddings([text], engine=engine)[0]
           ^^^^^^^^^^^^^^^^^^^^^^^^^^^^^^^^^^^^^^^^^^^^^^^^^^^^
  File "C:\Users\JSHARRATT\Documents\EES_GPT\backend\env\Lib\site-packages\langchain\embeddings\openai.py", line 206, in _get_len_safe_embeddings
    response = embed_with_retry(
               ^^^^^^^^^^^^^^^^^
  File "C:\Users\JSHARRATT\Documents\EES_GPT\backend\env\Lib\site-packages\langchain\embeddings\openai.py", line 53, in embed_with_retry
    return _completion_with_retry(**kwargs)
           ^^^^^^^^^^^^^^^^^^^^^^^^^^^^^^^^
  File "C:\Users\JSHARRATT\Documents\EES_GPT\backend\env\Lib\site-packages\tenacity\__init__.py", line 289, in wrapped_f
    return self(f, *args, **kw)
           ^^^^^^^^^^^^^^^^^^^^
  File "C:\Users\JSHARRATT\Documents\EES_GPT\backend\env\Lib\site-packages\tenacity\__init__.py", line 379, in __call__
    do = self.iter(retry_state=retry_state)
         ^^^^^^^^^^^^^^^^^^^^^^^^^^^^^^^^^^
  File "C:\Users\JSHARRATT\Documents\EES_GPT\backend\env\Lib\site-packages\tenacity\__init__.py", line 314, in iter
    return fut.result()
           ^^^^^^^^^^^^
  File "C:\Program Files\Python311\Lib\concurrent\futures\_base.py", line 449, in result
    return self.__get_result()
           ^^^^^^^^^^^^^^^^^^^
  File "C:\Program Files\Python311\Lib\concurrent\futures\_base.py", line 401, in __get_result
    raise self._exception
  File "C:\Users\JSHARRATT\Documents\EES_GPT\backend\env\Lib\site-packages\tenacity\__init__.py", line 382, in __call__
    result = fn(*args, **kwargs)
             ^^^^^^^^^^^^^^^^^^^
  File "C:\Users\JSHARRATT\Documents\EES_GPT\backend\env\Lib\site-packages\langchain\embeddings\openai.py", line 51, in _completion_with_retry
    return embeddings.client.create(**kwargs)
           ^^^^^^^^^^^^^^^^^^^^^^^^^^^^^^^^^^
  File "C:\Users\JSHARRATT\Documents\EES_GPT\backend\env\Lib\site-packages\openai\api_resources\embedding.py", line 33, in create
    response = super().create(*args, **kwargs)
               ^^^^^^^^^^^^^^^^^^^^^^^^^^^^^^^
  File "C:\Users\JSHARRATT\Documents\EES_GPT\backend\env\Lib\site-packages\openai\api_resources\abstract\engine_api_resource.py", line 153, in create
    response, _, api_key = requestor.request(
                           ^^^^^^^^^^^^^^^^^^
  File "C:\Users\JSHARRATT\Documents\EES_GPT\backend\env\Lib\site-packages\openai\api_requestor.py", line 298, in request
    resp, got_stream = self._interpret_response(result, stream)
                       ^^^^^^^^^^^^^^^^^^^^^^^^^^^^^^^^^^^^^^^^
  File "C:\Users\JSHARRATT\Documents\EES_GPT\backend\env\Lib\site-packages\openai\api_requestor.py", line 700, in _interpret_response
    self._interpret_response_line(
  File "C:\Users\JSHARRATT\Documents\EES_GPT\backend\env\Lib\site-packages\openai\api_requestor.py", line 763, in _interpret_response_line
    raise self.handle_error_response(
openai.error.AuthenticationError: <empty message>
ERROR 2023-06-13 13:38:14,438 log 20724 13304 Internal Server Error: /api/
Traceback (most recent call last):
  File "C:\Users\JSHARRATT\Documents\EES_GPT\backend\env\Lib\site-packages\django\core\handlers\exception.py", line 55, in inner
    response = get_response(request)
               ^^^^^^^^^^^^^^^^^^^^^
  File "C:\Users\JSHARRATT\Documents\EES_GPT\backend\env\Lib\site-packages\django\core\handlers\base.py", line 197, in _get_response
    response = wrapped_callback(request, *callback_args, **callback_kwargs)
               ^^^^^^^^^^^^^^^^^^^^^^^^^^^^^^^^^^^^^^^^^^^^^^^^^^^^^^^^^^^^
  File "C:\Users\JSHARRATT\Documents\EES_GPT\backend\env\Lib\site-packages\asgiref\sync.py", line 277, in __call__
    return call_result.result()
           ^^^^^^^^^^^^^^^^^^^^
  File "C:\Program Files\Python311\Lib\concurrent\futures\_base.py", line 449, in result
    return self.__get_result()
           ^^^^^^^^^^^^^^^^^^^
  File "C:\Program Files\Python311\Lib\concurrent\futures\_base.py", line 401, in __get_result
    raise self._exception
  File "C:\Users\JSHARRATT\Documents\EES_GPT\backend\env\Lib\site-packages\asgiref\sync.py", line 353, in main_wrap
    result = await self.awaitable(*args, **kwargs)
             ^^^^^^^^^^^^^^^^^^^^^^^^^^^^^^^^^^^^^
  File "C:\Users\JSHARRATT\Documents\EES_GPT\backend\env\Lib\site-packages\adrf\views.py", line 63, in async_dispatch
    response = self.handle_exception(exc)
               ^^^^^^^^^^^^^^^^^^^^^^^^^^
  File "C:\Users\JSHARRATT\Documents\EES_GPT\backend\env\Lib\site-packages\rest_framework\views.py", line 469, in handle_exception
    self.raise_uncaught_exception(exc)
  File "C:\Users\JSHARRATT\Documents\EES_GPT\backend\env\Lib\site-packages\rest_framework\views.py", line 480, in raise_uncaught_exception
    raise exc
  File "C:\Users\JSHARRATT\Documents\EES_GPT\backend\env\Lib\site-packages\adrf\views.py", line 60, in async_dispatch
    response = await handler(request, *args, **kwargs)
               ^^^^^^^^^^^^^^^^^^^^^^^^^^^^^^^^^^^^^^^
  File "C:\Users\JSHARRATT\Documents\EES_GPT\backend\env\Lib\site-packages\adrf\decorators.py", line 44, in handler
    return await func(*args, **kwargs)
           ^^^^^^^^^^^^^^^^^^^^^^^^^^^
  File "C:\Users\JSHARRATT\Documents\EES_GPT\backend\django_proj\api\views.py", line 37, in handler
    similar_docs = vector_store.similarity_search(query = stripped_question, int = 4)
                   ^^^^^^^^^^^^^^^^^^^^^^^^^^^^^^^^^^^^^^^^^^^^^^^^^^^^^^^^^^^^^^^^^^
  File "C:\Users\JSHARRATT\Documents\EES_GPT\backend\env\Lib\site-packages\langchain\vectorstores\pinecone.py", line 148, in similarity_search
    query_obj = self._embedding_function(query)
                ^^^^^^^^^^^^^^^^^^^^^^^^^^^^^^^
  File "C:\Users\JSHARRATT\Documents\EES_GPT\backend\env\Lib\site-packages\langchain\embeddings\openai.py", line 280, in embed_query
    embedding = self._embedding_func(text, engine=self.query_model_name)
                ^^^^^^^^^^^^^^^^^^^^^^^^^^^^^^^^^^^^^^^^^^^^^^^^^^^^^^^^
  File "C:\Users\JSHARRATT\Documents\EES_GPT\backend\env\Lib\site-packages\langchain\embeddings\openai.py", line 236, in _embedding_func
    return self._get_len_safe_embeddings([text], engine=engine)[0]
           ^^^^^^^^^^^^^^^^^^^^^^^^^^^^^^^^^^^^^^^^^^^^^^^^^^^^
  File "C:\Users\JSHARRATT\Documents\EES_GPT\backend\env\Lib\site-packages\langchain\embeddings\openai.py", line 206, in _get_len_safe_embeddings
    response = embed_with_retry(
               ^^^^^^^^^^^^^^^^^
  File "C:\Users\JSHARRATT\Documents\EES_GPT\backend\env\Lib\site-packages\langchain\embeddings\openai.py", line 53, in embed_with_retry
    return _completion_with_retry(**kwargs)
           ^^^^^^^^^^^^^^^^^^^^^^^^^^^^^^^^
  File "C:\Users\JSHARRATT\Documents\EES_GPT\backend\env\Lib\site-packages\tenacity\__init__.py", line 289, in wrapped_f
    return self(f, *args, **kw)
           ^^^^^^^^^^^^^^^^^^^^
  File "C:\Users\JSHARRATT\Documents\EES_GPT\backend\env\Lib\site-packages\tenacity\__init__.py", line 379, in __call__
    do = self.iter(retry_state=retry_state)
         ^^^^^^^^^^^^^^^^^^^^^^^^^^^^^^^^^^
  File "C:\Users\JSHARRATT\Documents\EES_GPT\backend\env\Lib\site-packages\tenacity\__init__.py", line 314, in iter
    return fut.result()
           ^^^^^^^^^^^^
  File "C:\Program Files\Python311\Lib\concurrent\futures\_base.py", line 449, in result
    return self.__get_result()
           ^^^^^^^^^^^^^^^^^^^
  File "C:\Program Files\Python311\Lib\concurrent\futures\_base.py", line 401, in __get_result
    raise self._exception
  File "C:\Users\JSHARRATT\Documents\EES_GPT\backend\env\Lib\site-packages\tenacity\__init__.py", line 382, in __call__
    result = fn(*args, **kwargs)
             ^^^^^^^^^^^^^^^^^^^
  File "C:\Users\JSHARRATT\Documents\EES_GPT\backend\env\Lib\site-packages\langchain\embeddings\openai.py", line 51, in _completion_with_retry
    return embeddings.client.create(**kwargs)
           ^^^^^^^^^^^^^^^^^^^^^^^^^^^^^^^^^^
  File "C:\Users\JSHARRATT\Documents\EES_GPT\backend\env\Lib\site-packages\openai\api_resources\embedding.py", line 33, in create
    response = super().create(*args, **kwargs)
               ^^^^^^^^^^^^^^^^^^^^^^^^^^^^^^^
  File "C:\Users\JSHARRATT\Documents\EES_GPT\backend\env\Lib\site-packages\openai\api_resources\abstract\engine_api_resource.py", line 153, in create
    response, _, api_key = requestor.request(
                           ^^^^^^^^^^^^^^^^^^
  File "C:\Users\JSHARRATT\Documents\EES_GPT\backend\env\Lib\site-packages\openai\api_requestor.py", line 298, in request
    resp, got_stream = self._interpret_response(result, stream)
                       ^^^^^^^^^^^^^^^^^^^^^^^^^^^^^^^^^^^^^^^^
  File "C:\Users\JSHARRATT\Documents\EES_GPT\backend\env\Lib\site-packages\openai\api_requestor.py", line 700, in _interpret_response
    self._interpret_response_line(
  File "C:\Users\JSHARRATT\Documents\EES_GPT\backend\env\Lib\site-packages\openai\api_requestor.py", line 763, in _interpret_response_line
    raise self.handle_error_response(
openai.error.AuthenticationError: <empty message>
ERROR 2023-06-13 13:43:37,631 log 11120 1652 Internal Server Error: /api/
Traceback (most recent call last):
  File "C:\Users\JSHARRATT\Documents\EES_GPT\backend\env\Lib\site-packages\django\core\handlers\exception.py", line 55, in inner
    response = get_response(request)
               ^^^^^^^^^^^^^^^^^^^^^
  File "C:\Users\JSHARRATT\Documents\EES_GPT\backend\env\Lib\site-packages\django\core\handlers\base.py", line 197, in _get_response
    response = wrapped_callback(request, *callback_args, **callback_kwargs)
               ^^^^^^^^^^^^^^^^^^^^^^^^^^^^^^^^^^^^^^^^^^^^^^^^^^^^^^^^^^^^
  File "C:\Users\JSHARRATT\Documents\EES_GPT\backend\env\Lib\site-packages\asgiref\sync.py", line 277, in __call__
    return call_result.result()
           ^^^^^^^^^^^^^^^^^^^^
  File "C:\Program Files\Python311\Lib\concurrent\futures\_base.py", line 449, in result
    return self.__get_result()
           ^^^^^^^^^^^^^^^^^^^
  File "C:\Program Files\Python311\Lib\concurrent\futures\_base.py", line 401, in __get_result
    raise self._exception
  File "C:\Users\JSHARRATT\Documents\EES_GPT\backend\env\Lib\site-packages\asgiref\sync.py", line 353, in main_wrap
    result = await self.awaitable(*args, **kwargs)
             ^^^^^^^^^^^^^^^^^^^^^^^^^^^^^^^^^^^^^
  File "C:\Users\JSHARRATT\Documents\EES_GPT\backend\env\Lib\site-packages\adrf\views.py", line 63, in async_dispatch
    response = self.handle_exception(exc)
               ^^^^^^^^^^^^^^^^^^^^^^^^^^
  File "C:\Users\JSHARRATT\Documents\EES_GPT\backend\env\Lib\site-packages\rest_framework\views.py", line 469, in handle_exception
    self.raise_uncaught_exception(exc)
  File "C:\Users\JSHARRATT\Documents\EES_GPT\backend\env\Lib\site-packages\rest_framework\views.py", line 480, in raise_uncaught_exception
    raise exc
  File "C:\Users\JSHARRATT\Documents\EES_GPT\backend\env\Lib\site-packages\adrf\views.py", line 60, in async_dispatch
    response = await handler(request, *args, **kwargs)
               ^^^^^^^^^^^^^^^^^^^^^^^^^^^^^^^^^^^^^^^
  File "C:\Users\JSHARRATT\Documents\EES_GPT\backend\env\Lib\site-packages\adrf\decorators.py", line 44, in handler
    return await func(*args, **kwargs)
           ^^^^^^^^^^^^^^^^^^^^^^^^^^^
  File "C:\Users\JSHARRATT\Documents\EES_GPT\backend\django_proj\api\views.py", line 38, in handler
    similar_docs = vector_store.similarity_search(query = stripped_question, int = 4)
                   ^^^^^^^^^^^^^^^^^^^^^^^^^^^^^^^^^^^^^^^^^^^^^^^^^^^^^^^^^^^^^^^^^^
  File "C:\Users\JSHARRATT\Documents\EES_GPT\backend\env\Lib\site-packages\langchain\vectorstores\pinecone.py", line 148, in similarity_search
    query_obj = self._embedding_function(query)
                ^^^^^^^^^^^^^^^^^^^^^^^^^^^^^^^
  File "C:\Users\JSHARRATT\Documents\EES_GPT\backend\env\Lib\site-packages\langchain\embeddings\openai.py", line 280, in embed_query
    embedding = self._embedding_func(text, engine=self.query_model_name)
                ^^^^^^^^^^^^^^^^^^^^^^^^^^^^^^^^^^^^^^^^^^^^^^^^^^^^^^^^
  File "C:\Users\JSHARRATT\Documents\EES_GPT\backend\env\Lib\site-packages\langchain\embeddings\openai.py", line 236, in _embedding_func
    return self._get_len_safe_embeddings([text], engine=engine)[0]
           ^^^^^^^^^^^^^^^^^^^^^^^^^^^^^^^^^^^^^^^^^^^^^^^^^^^^
  File "C:\Users\JSHARRATT\Documents\EES_GPT\backend\env\Lib\site-packages\langchain\embeddings\openai.py", line 206, in _get_len_safe_embeddings
    response = embed_with_retry(
               ^^^^^^^^^^^^^^^^^
  File "C:\Users\JSHARRATT\Documents\EES_GPT\backend\env\Lib\site-packages\langchain\embeddings\openai.py", line 53, in embed_with_retry
    return _completion_with_retry(**kwargs)
           ^^^^^^^^^^^^^^^^^^^^^^^^^^^^^^^^
  File "C:\Users\JSHARRATT\Documents\EES_GPT\backend\env\Lib\site-packages\tenacity\__init__.py", line 289, in wrapped_f
    return self(f, *args, **kw)
           ^^^^^^^^^^^^^^^^^^^^
  File "C:\Users\JSHARRATT\Documents\EES_GPT\backend\env\Lib\site-packages\tenacity\__init__.py", line 379, in __call__
    do = self.iter(retry_state=retry_state)
         ^^^^^^^^^^^^^^^^^^^^^^^^^^^^^^^^^^
  File "C:\Users\JSHARRATT\Documents\EES_GPT\backend\env\Lib\site-packages\tenacity\__init__.py", line 314, in iter
    return fut.result()
           ^^^^^^^^^^^^
  File "C:\Program Files\Python311\Lib\concurrent\futures\_base.py", line 449, in result
    return self.__get_result()
           ^^^^^^^^^^^^^^^^^^^
  File "C:\Program Files\Python311\Lib\concurrent\futures\_base.py", line 401, in __get_result
    raise self._exception
  File "C:\Users\JSHARRATT\Documents\EES_GPT\backend\env\Lib\site-packages\tenacity\__init__.py", line 382, in __call__
    result = fn(*args, **kwargs)
             ^^^^^^^^^^^^^^^^^^^
  File "C:\Users\JSHARRATT\Documents\EES_GPT\backend\env\Lib\site-packages\langchain\embeddings\openai.py", line 51, in _completion_with_retry
    return embeddings.client.create(**kwargs)
           ^^^^^^^^^^^^^^^^^^^^^^^^^^^^^^^^^^
  File "C:\Users\JSHARRATT\Documents\EES_GPT\backend\env\Lib\site-packages\openai\api_resources\embedding.py", line 33, in create
    response = super().create(*args, **kwargs)
               ^^^^^^^^^^^^^^^^^^^^^^^^^^^^^^^
  File "C:\Users\JSHARRATT\Documents\EES_GPT\backend\env\Lib\site-packages\openai\api_resources\abstract\engine_api_resource.py", line 153, in create
    response, _, api_key = requestor.request(
                           ^^^^^^^^^^^^^^^^^^
  File "C:\Users\JSHARRATT\Documents\EES_GPT\backend\env\Lib\site-packages\openai\api_requestor.py", line 298, in request
    resp, got_stream = self._interpret_response(result, stream)
                       ^^^^^^^^^^^^^^^^^^^^^^^^^^^^^^^^^^^^^^^^
  File "C:\Users\JSHARRATT\Documents\EES_GPT\backend\env\Lib\site-packages\openai\api_requestor.py", line 700, in _interpret_response
    self._interpret_response_line(
  File "C:\Users\JSHARRATT\Documents\EES_GPT\backend\env\Lib\site-packages\openai\api_requestor.py", line 763, in _interpret_response_line
    raise self.handle_error_response(
openai.error.AuthenticationError: <empty message>
ERROR 2023-06-13 13:45:06,652 log 21824 8032 Internal Server Error: /api/
Traceback (most recent call last):
  File "C:\Users\JSHARRATT\Documents\EES_GPT\backend\env\Lib\site-packages\django\core\handlers\exception.py", line 55, in inner
    response = get_response(request)
               ^^^^^^^^^^^^^^^^^^^^^
  File "C:\Users\JSHARRATT\Documents\EES_GPT\backend\env\Lib\site-packages\django\core\handlers\base.py", line 197, in _get_response
    response = wrapped_callback(request, *callback_args, **callback_kwargs)
               ^^^^^^^^^^^^^^^^^^^^^^^^^^^^^^^^^^^^^^^^^^^^^^^^^^^^^^^^^^^^
  File "C:\Users\JSHARRATT\Documents\EES_GPT\backend\env\Lib\site-packages\asgiref\sync.py", line 277, in __call__
    return call_result.result()
           ^^^^^^^^^^^^^^^^^^^^
  File "C:\Program Files\Python311\Lib\concurrent\futures\_base.py", line 449, in result
    return self.__get_result()
           ^^^^^^^^^^^^^^^^^^^
  File "C:\Program Files\Python311\Lib\concurrent\futures\_base.py", line 401, in __get_result
    raise self._exception
  File "C:\Users\JSHARRATT\Documents\EES_GPT\backend\env\Lib\site-packages\asgiref\sync.py", line 353, in main_wrap
    result = await self.awaitable(*args, **kwargs)
             ^^^^^^^^^^^^^^^^^^^^^^^^^^^^^^^^^^^^^
  File "C:\Users\JSHARRATT\Documents\EES_GPT\backend\env\Lib\site-packages\adrf\views.py", line 63, in async_dispatch
    response = self.handle_exception(exc)
               ^^^^^^^^^^^^^^^^^^^^^^^^^^
  File "C:\Users\JSHARRATT\Documents\EES_GPT\backend\env\Lib\site-packages\rest_framework\views.py", line 469, in handle_exception
    self.raise_uncaught_exception(exc)
  File "C:\Users\JSHARRATT\Documents\EES_GPT\backend\env\Lib\site-packages\rest_framework\views.py", line 480, in raise_uncaught_exception
    raise exc
  File "C:\Users\JSHARRATT\Documents\EES_GPT\backend\env\Lib\site-packages\adrf\views.py", line 60, in async_dispatch
    response = await handler(request, *args, **kwargs)
               ^^^^^^^^^^^^^^^^^^^^^^^^^^^^^^^^^^^^^^^
  File "C:\Users\JSHARRATT\Documents\EES_GPT\backend\env\Lib\site-packages\adrf\decorators.py", line 44, in handler
    return await func(*args, **kwargs)
           ^^^^^^^^^^^^^^^^^^^^^^^^^^^
  File "C:\Users\JSHARRATT\Documents\EES_GPT\backend\django_proj\api\views.py", line 36, in handler
    similar_docs = vector_store.similarity_search(query = stripped_question, int = 4)
                   ^^^^^^^^^^^^^^^^^^^^^^^^^^^^^^^^^^^^^^^^^^^^^^^^^^^^^^^^^^^^^^^^^^
  File "C:\Users\JSHARRATT\Documents\EES_GPT\backend\env\Lib\site-packages\langchain\vectorstores\pinecone.py", line 148, in similarity_search
    query_obj = self._embedding_function(query)
                ^^^^^^^^^^^^^^^^^^^^^^^^^^^^^^^
  File "C:\Users\JSHARRATT\Documents\EES_GPT\backend\env\Lib\site-packages\langchain\embeddings\openai.py", line 280, in embed_query
    embedding = self._embedding_func(text, engine=self.query_model_name)
                ^^^^^^^^^^^^^^^^^^^^^^^^^^^^^^^^^^^^^^^^^^^^^^^^^^^^^^^^
  File "C:\Users\JSHARRATT\Documents\EES_GPT\backend\env\Lib\site-packages\langchain\embeddings\openai.py", line 236, in _embedding_func
    return self._get_len_safe_embeddings([text], engine=engine)[0]
           ^^^^^^^^^^^^^^^^^^^^^^^^^^^^^^^^^^^^^^^^^^^^^^^^^^^^
  File "C:\Users\JSHARRATT\Documents\EES_GPT\backend\env\Lib\site-packages\langchain\embeddings\openai.py", line 206, in _get_len_safe_embeddings
    response = embed_with_retry(
               ^^^^^^^^^^^^^^^^^
  File "C:\Users\JSHARRATT\Documents\EES_GPT\backend\env\Lib\site-packages\langchain\embeddings\openai.py", line 53, in embed_with_retry
    return _completion_with_retry(**kwargs)
           ^^^^^^^^^^^^^^^^^^^^^^^^^^^^^^^^
  File "C:\Users\JSHARRATT\Documents\EES_GPT\backend\env\Lib\site-packages\tenacity\__init__.py", line 289, in wrapped_f
    return self(f, *args, **kw)
           ^^^^^^^^^^^^^^^^^^^^
  File "C:\Users\JSHARRATT\Documents\EES_GPT\backend\env\Lib\site-packages\tenacity\__init__.py", line 379, in __call__
    do = self.iter(retry_state=retry_state)
         ^^^^^^^^^^^^^^^^^^^^^^^^^^^^^^^^^^
  File "C:\Users\JSHARRATT\Documents\EES_GPT\backend\env\Lib\site-packages\tenacity\__init__.py", line 314, in iter
    return fut.result()
           ^^^^^^^^^^^^
  File "C:\Program Files\Python311\Lib\concurrent\futures\_base.py", line 449, in result
    return self.__get_result()
           ^^^^^^^^^^^^^^^^^^^
  File "C:\Program Files\Python311\Lib\concurrent\futures\_base.py", line 401, in __get_result
    raise self._exception
  File "C:\Users\JSHARRATT\Documents\EES_GPT\backend\env\Lib\site-packages\tenacity\__init__.py", line 382, in __call__
    result = fn(*args, **kwargs)
             ^^^^^^^^^^^^^^^^^^^
  File "C:\Users\JSHARRATT\Documents\EES_GPT\backend\env\Lib\site-packages\langchain\embeddings\openai.py", line 51, in _completion_with_retry
    return embeddings.client.create(**kwargs)
           ^^^^^^^^^^^^^^^^^^^^^^^^^^^^^^^^^^
  File "C:\Users\JSHARRATT\Documents\EES_GPT\backend\env\Lib\site-packages\openai\api_resources\embedding.py", line 33, in create
    response = super().create(*args, **kwargs)
               ^^^^^^^^^^^^^^^^^^^^^^^^^^^^^^^
  File "C:\Users\JSHARRATT\Documents\EES_GPT\backend\env\Lib\site-packages\openai\api_resources\abstract\engine_api_resource.py", line 153, in create
    response, _, api_key = requestor.request(
                           ^^^^^^^^^^^^^^^^^^
  File "C:\Users\JSHARRATT\Documents\EES_GPT\backend\env\Lib\site-packages\openai\api_requestor.py", line 298, in request
    resp, got_stream = self._interpret_response(result, stream)
                       ^^^^^^^^^^^^^^^^^^^^^^^^^^^^^^^^^^^^^^^^
  File "C:\Users\JSHARRATT\Documents\EES_GPT\backend\env\Lib\site-packages\openai\api_requestor.py", line 700, in _interpret_response
    self._interpret_response_line(
  File "C:\Users\JSHARRATT\Documents\EES_GPT\backend\env\Lib\site-packages\openai\api_requestor.py", line 763, in _interpret_response_line
    raise self.handle_error_response(
openai.error.AuthenticationError: <empty message>
ERROR 2023-06-13 13:50:24,739 log 19376 2196 Internal Server Error: /api/
Traceback (most recent call last):
  File "C:\Users\JSHARRATT\Documents\EES_GPT\backend\env\Lib\site-packages\django\core\handlers\exception.py", line 55, in inner
    response = get_response(request)
               ^^^^^^^^^^^^^^^^^^^^^
  File "C:\Users\JSHARRATT\Documents\EES_GPT\backend\env\Lib\site-packages\django\core\handlers\base.py", line 197, in _get_response
    response = wrapped_callback(request, *callback_args, **callback_kwargs)
               ^^^^^^^^^^^^^^^^^^^^^^^^^^^^^^^^^^^^^^^^^^^^^^^^^^^^^^^^^^^^
  File "C:\Users\JSHARRATT\Documents\EES_GPT\backend\env\Lib\site-packages\asgiref\sync.py", line 277, in __call__
    return call_result.result()
           ^^^^^^^^^^^^^^^^^^^^
  File "C:\Program Files\Python311\Lib\concurrent\futures\_base.py", line 449, in result
    return self.__get_result()
           ^^^^^^^^^^^^^^^^^^^
  File "C:\Program Files\Python311\Lib\concurrent\futures\_base.py", line 401, in __get_result
    raise self._exception
  File "C:\Users\JSHARRATT\Documents\EES_GPT\backend\env\Lib\site-packages\asgiref\sync.py", line 353, in main_wrap
    result = await self.awaitable(*args, **kwargs)
             ^^^^^^^^^^^^^^^^^^^^^^^^^^^^^^^^^^^^^
  File "C:\Users\JSHARRATT\Documents\EES_GPT\backend\env\Lib\site-packages\adrf\views.py", line 63, in async_dispatch
    response = self.handle_exception(exc)
               ^^^^^^^^^^^^^^^^^^^^^^^^^^
  File "C:\Users\JSHARRATT\Documents\EES_GPT\backend\env\Lib\site-packages\rest_framework\views.py", line 469, in handle_exception
    self.raise_uncaught_exception(exc)
  File "C:\Users\JSHARRATT\Documents\EES_GPT\backend\env\Lib\site-packages\rest_framework\views.py", line 480, in raise_uncaught_exception
    raise exc
  File "C:\Users\JSHARRATT\Documents\EES_GPT\backend\env\Lib\site-packages\adrf\views.py", line 60, in async_dispatch
    response = await handler(request, *args, **kwargs)
               ^^^^^^^^^^^^^^^^^^^^^^^^^^^^^^^^^^^^^^^
  File "C:\Users\JSHARRATT\Documents\EES_GPT\backend\env\Lib\site-packages\adrf\decorators.py", line 44, in handler
    return await func(*args, **kwargs)
           ^^^^^^^^^^^^^^^^^^^^^^^^^^^
  File "C:\Users\JSHARRATT\Documents\EES_GPT\backend\django_proj\api\views.py", line 38, in handler
    similar_docs = vector_store.similarity_search(query = stripped_question, int = 4)
                   ^^^^^^^^^^^^^^^^^^^^^^^^^^^^^^^^^^^^^^^^^^^^^^^^^^^^^^^^^^^^^^^^^^
  File "C:\Users\JSHARRATT\Documents\EES_GPT\backend\env\Lib\site-packages\langchain\vectorstores\pinecone.py", line 148, in similarity_search
    query_obj = self._embedding_function(query)
                ^^^^^^^^^^^^^^^^^^^^^^^^^^^^^^^
  File "C:\Users\JSHARRATT\Documents\EES_GPT\backend\env\Lib\site-packages\langchain\embeddings\openai.py", line 280, in embed_query
    embedding = self._embedding_func(text, engine=self.query_model_name)
                ^^^^^^^^^^^^^^^^^^^^^^^^^^^^^^^^^^^^^^^^^^^^^^^^^^^^^^^^
  File "C:\Users\JSHARRATT\Documents\EES_GPT\backend\env\Lib\site-packages\langchain\embeddings\openai.py", line 236, in _embedding_func
    return self._get_len_safe_embeddings([text], engine=engine)[0]
           ^^^^^^^^^^^^^^^^^^^^^^^^^^^^^^^^^^^^^^^^^^^^^^^^^^^^
  File "C:\Users\JSHARRATT\Documents\EES_GPT\backend\env\Lib\site-packages\langchain\embeddings\openai.py", line 206, in _get_len_safe_embeddings
    response = embed_with_retry(
               ^^^^^^^^^^^^^^^^^
  File "C:\Users\JSHARRATT\Documents\EES_GPT\backend\env\Lib\site-packages\langchain\embeddings\openai.py", line 53, in embed_with_retry
    return _completion_with_retry(**kwargs)
           ^^^^^^^^^^^^^^^^^^^^^^^^^^^^^^^^
  File "C:\Users\JSHARRATT\Documents\EES_GPT\backend\env\Lib\site-packages\tenacity\__init__.py", line 289, in wrapped_f
    return self(f, *args, **kw)
           ^^^^^^^^^^^^^^^^^^^^
  File "C:\Users\JSHARRATT\Documents\EES_GPT\backend\env\Lib\site-packages\tenacity\__init__.py", line 379, in __call__
    do = self.iter(retry_state=retry_state)
         ^^^^^^^^^^^^^^^^^^^^^^^^^^^^^^^^^^
  File "C:\Users\JSHARRATT\Documents\EES_GPT\backend\env\Lib\site-packages\tenacity\__init__.py", line 314, in iter
    return fut.result()
           ^^^^^^^^^^^^
  File "C:\Program Files\Python311\Lib\concurrent\futures\_base.py", line 449, in result
    return self.__get_result()
           ^^^^^^^^^^^^^^^^^^^
  File "C:\Program Files\Python311\Lib\concurrent\futures\_base.py", line 401, in __get_result
    raise self._exception
  File "C:\Users\JSHARRATT\Documents\EES_GPT\backend\env\Lib\site-packages\tenacity\__init__.py", line 382, in __call__
    result = fn(*args, **kwargs)
             ^^^^^^^^^^^^^^^^^^^
  File "C:\Users\JSHARRATT\Documents\EES_GPT\backend\env\Lib\site-packages\langchain\embeddings\openai.py", line 51, in _completion_with_retry
    return embeddings.client.create(**kwargs)
           ^^^^^^^^^^^^^^^^^^^^^^^^^^^^^^^^^^
  File "C:\Users\JSHARRATT\Documents\EES_GPT\backend\env\Lib\site-packages\openai\api_resources\embedding.py", line 33, in create
    response = super().create(*args, **kwargs)
               ^^^^^^^^^^^^^^^^^^^^^^^^^^^^^^^
  File "C:\Users\JSHARRATT\Documents\EES_GPT\backend\env\Lib\site-packages\openai\api_resources\abstract\engine_api_resource.py", line 153, in create
    response, _, api_key = requestor.request(
                           ^^^^^^^^^^^^^^^^^^
  File "C:\Users\JSHARRATT\Documents\EES_GPT\backend\env\Lib\site-packages\openai\api_requestor.py", line 298, in request
    resp, got_stream = self._interpret_response(result, stream)
                       ^^^^^^^^^^^^^^^^^^^^^^^^^^^^^^^^^^^^^^^^
  File "C:\Users\JSHARRATT\Documents\EES_GPT\backend\env\Lib\site-packages\openai\api_requestor.py", line 700, in _interpret_response
    self._interpret_response_line(
  File "C:\Users\JSHARRATT\Documents\EES_GPT\backend\env\Lib\site-packages\openai\api_requestor.py", line 763, in _interpret_response_line
    raise self.handle_error_response(
openai.error.AuthenticationError: <empty message>
ERROR 2023-06-15 10:16:19,805 log 12968 9468 Internal Server Error: /api/
Traceback (most recent call last):
  File "C:\Users\JSHARRATT\Documents\EES_GPT\backend\env\Lib\site-packages\django\core\handlers\exception.py", line 55, in inner
    response = get_response(request)
               ^^^^^^^^^^^^^^^^^^^^^
  File "C:\Users\JSHARRATT\Documents\EES_GPT\backend\env\Lib\site-packages\django\core\handlers\base.py", line 197, in _get_response
    response = wrapped_callback(request, *callback_args, **callback_kwargs)
               ^^^^^^^^^^^^^^^^^^^^^^^^^^^^^^^^^^^^^^^^^^^^^^^^^^^^^^^^^^^^
  File "C:\Users\JSHARRATT\Documents\EES_GPT\backend\env\Lib\site-packages\asgiref\sync.py", line 277, in __call__
    return call_result.result()
           ^^^^^^^^^^^^^^^^^^^^
  File "C:\Program Files\Python311\Lib\concurrent\futures\_base.py", line 449, in result
    return self.__get_result()
           ^^^^^^^^^^^^^^^^^^^
  File "C:\Program Files\Python311\Lib\concurrent\futures\_base.py", line 401, in __get_result
    raise self._exception
  File "C:\Users\JSHARRATT\Documents\EES_GPT\backend\env\Lib\site-packages\asgiref\sync.py", line 353, in main_wrap
    result = await self.awaitable(*args, **kwargs)
             ^^^^^^^^^^^^^^^^^^^^^^^^^^^^^^^^^^^^^
  File "C:\Users\JSHARRATT\Documents\EES_GPT\backend\env\Lib\site-packages\adrf\views.py", line 63, in async_dispatch
    response = self.handle_exception(exc)
               ^^^^^^^^^^^^^^^^^^^^^^^^^^
  File "C:\Users\JSHARRATT\Documents\EES_GPT\backend\env\Lib\site-packages\rest_framework\views.py", line 469, in handle_exception
    self.raise_uncaught_exception(exc)
  File "C:\Users\JSHARRATT\Documents\EES_GPT\backend\env\Lib\site-packages\rest_framework\views.py", line 480, in raise_uncaught_exception
    raise exc
  File "C:\Users\JSHARRATT\Documents\EES_GPT\backend\env\Lib\site-packages\adrf\views.py", line 60, in async_dispatch
    response = await handler(request, *args, **kwargs)
               ^^^^^^^^^^^^^^^^^^^^^^^^^^^^^^^^^^^^^^^
  File "C:\Users\JSHARRATT\Documents\EES_GPT\backend\env\Lib\site-packages\adrf\decorators.py", line 44, in handler
    return await func(*args, **kwargs)
           ^^^^^^^^^^^^^^^^^^^^^^^^^^^
  File "C:\Users\JSHARRATT\Documents\EES_GPT\backend\django_proj\api\views.py", line 37, in handler
    similar_docs = vector_store.similarity_search(query = stripped_question, int = 4)
                   ^^^^^^^^^^^^^^^^^^^^^^^^^^^^^^^^^^^^^^^^^^^^^^^^^^^^^^^^^^^^^^^^^^
  File "C:\Users\JSHARRATT\Documents\EES_GPT\backend\env\Lib\site-packages\langchain\vectorstores\pinecone.py", line 155, in similarity_search
    docs_and_scores = self.similarity_search_with_score(
                      ^^^^^^^^^^^^^^^^^^^^^^^^^^^^^^^^^^
TypeError: Pinecone.similarity_search_with_score() got an unexpected keyword argument 'int'
